<?xml version="1.0" ?>
<!-- =================================================================================== -->
<!-- |    This document was autogenerated by xacro from chat.xacro                     | -->
<!-- |    EDITING THIS FILE BY HAND IS NOT RECOMMENDED                                 | -->
<!-- =================================================================================== -->
<robot name="robot_name">
  <!-- Mundo (World) -->
  <link name="world"/>
  <joint name="world_joint" type="fixed">
    <origin rpy="0.0 0.0 0.0" xyz="0.0 0.0 0.0"/>
    <parent link="world"/>
    <child link="base_link"/>
  </joint>
  <!-- Base Link -->
  <link name="base_link">
    <inertial>
      <origin rpy="0 0 0" xyz="0 0 0.075"/>
      <mass value="20"/>
      <inertia ixx="0.1875" ixy="0.0" ixz="0.0" iyy="0.1875" iyz="0.0" izz="0.3"/>
    </inertial>
    <visual>
      <origin rpy="0 0 0" xyz="0 0 0.075"/>
      <geometry>
        <cylinder length="0.15" radius="0.15"/>
      </geometry>
      <material name="grey">
        <color rgba="0.5 0.5 0.5 1"/>
      </material>
    </visual>
    <collision>
      <origin rpy="0 0 0" xyz="0 0 0.075"/>
      <geometry>
        <cylinder length="0.15" radius="0.15"/>
      </geometry>
    </collision>
  </link>
  <joint name="joint_1" type="revolute">
    <origin rpy="0.0 0.0 0.0" xyz="0.0 0.0 0.15"/>
    <parent link="base_link"/>
    <child link="link_1"/>
    <axis xyz="0.0 0.0 1"/>
    <limit effort="300.0" lower="0.0" upper="6.28318" velocity="1.0"/>
  </joint>
  <!-- Link 1 -->
  <link name="link_1">
    <inertial>
      <origin rpy="0 0 0" xyz="0 0 0.2"/>
      <mass value="5"/>
      <inertia ixx="0.07083333333333336" ixy="0.0" ixz="0.0" iyy="0.07083333333333336" iyz="0.0" izz="0.008333333333333335"/>
    </inertial>
    <visual>
      <origin rpy="0 0 0" xyz="0 0 0.2"/>
      <geometry>
        <cylinder length="0.4" radius="0.05"/>
      </geometry>
      <material name="grey">
        <color rgba="0.5 0.5 0.5 1"/>
      </material>
    </visual>
    <collision>
      <origin rpy="0 0 0" xyz="0 0 0.2"/>
      <geometry>
        <cylinder length="0.4" radius="0.05"/>
      </geometry>
    </collision>
  </link>
  <!-- Codo -->
  <link name="link_1_endlink">
    <inertial>
      <origin rpy="0 0 0" xyz="0 0 0.1"/>
      <mass value="1.6666666666666667"/>
      <inertia ixx="0.006944444444444446" ixy="0.0" ixz="0.0" iyy="0.006944444444444446" iyz="0.0" izz="0.0027777777777777783"/>
    </inertial>
    <visual>
      <origin rpy="0.0 0.0 0.0" xyz="0.0 0.0 0.1"/>
      <geometry>
        <cylinder length="0.2" radius="0.05500000000000001"/>
      </geometry>
      <material name="grey">
        <color rgba="0.5 0.5 0.5 1"/>
      </material>
    </visual>
    <collision>
      <origin rpy="0.0 0.0 0.0" xyz="0.0 0.0 0.1"/>
      <geometry>
        <cylinder length="0.2" radius="0.05500000000000001"/>
      </geometry>
    </collision>
  </link>
  <!-- Articulacion codo -->
  <joint name="link_1_endjoint" type="fixed">
    <origin rpy="0.0 1.570795 0.0" xyz="-0.05 0.0 0.4"/>
    <parent link="link_1"/>
    <child link="link_1_endlink"/>
  </joint>
  <joint name="joint_2" type="revolute">
    <origin rpy="0.0 0.0 0.0" xyz="0.1 0.0 0.4"/>
    <parent link="link_1"/>
    <child link="link_2"/>
    <axis xyz="1.0 0.0 0.0"/>
    <limit effort="300.0" lower="0.0" upper="3.14159" velocity="1.0"/>
  </joint>
  <!-- Link 2 -->
  <link name="link_2">
    <inertial>
      <origin rpy="0 0 0" xyz="0 0 0.15"/>
      <mass value="2"/>
      <inertia ixx="0.016666666666666666" ixy="0.0" ixz="0.0" iyy="0.016666666666666666" iyz="0.0" izz="0.003333333333333334"/>
    </inertial>
    <visual>
      <origin rpy="0 0 0" xyz="0 0 0.15"/>
      <geometry>
        <cylinder length="0.3" radius="0.05"/>
      </geometry>
      <material name="grey">
        <color rgba="0.5 0.5 0.5 1"/>
      </material>
    </visual>
    <collision>
      <origin rpy="0 0 0" xyz="0 0 0.15"/>
      <geometry>
        <cylinder length="0.3" radius="0.05"/>
      </geometry>
    </collision>
  </link>
  <!-- Link 2 end link -->
  <link name="link_2_endlink">
    <inertial>
      <origin rpy="0 0 0" xyz="0 0 0.07500000000000001"/>
      <mass value="1.0"/>
      <inertia ixx="0.002708333333333334" ixy="0.0" ixz="0.0" iyy="0.002708333333333334" iyz="0.0" izz="0.001666666666666667"/>
    </inertial>
    <visual>
      <origin rpy="0.0 0.0 0.0" xyz="0.0 0.0 0.07500000000000001"/>
      <geometry>
        <cylinder length="0.15000000000000002" radius="0.05500000000000001"/>
      </geometry>
      <material name="grey">
        <color rgba="0.5 0.5 0.5 1"/>
      </material>
    </visual>
    <collision>
      <origin rpy="0.0 0.0 0.0" xyz="0.0 0.0 0.07500000000000001"/>
      <geometry>
        <cylinder length="0.15000000000000002" radius="0.05500000000000001"/>
      </geometry>
    </collision>
  </link>
  <joint name="link_2_endjoint" type="fixed">
    <origin rpy="0.0 1.570795 0.0" xyz="-0.05 0.0 0.29"/>
    <parent link="link_2"/>
    <child link="link_2_endlink"/>
  </joint>
  <joint name="joint_3" type="revolute">
    <origin rpy="0.0 0.0 0.0" xyz="0.07500000000000001 0.0 0.25"/>
    <parent link="link_2"/>
    <child link="link_3"/>
    <axis xyz="1.0 0.0 0.0"/>
    <limit effort="300.0" lower="0.0" upper="6.28318" velocity="1.0"/>
  </joint>
  <!-- Link 3 -->
  <link name="link_3">
    <inertial>
      <origin rpy="0 0 0" xyz="0 0 0.15"/>
      <mass value="3"/>
      <inertia ixx="0.023125" ixy="0.0" ixz="0.0" iyy="0.023125" iyz="0.0" izz="0.0012500000000000002"/>
    </inertial>
    <visual>
      <origin rpy="0 0 0" xyz="0 0 0.15"/>
      <geometry>
        <cylinder length="0.3" radius="0.025"/>
      </geometry>
      <material name="grey">
        <color rgba="0.5 0.5 0.5 1"/>
      </material>
    </visual>
    <collision>
      <origin rpy="0 0 0" xyz="0 0 0.15"/>
      <geometry>
        <cylinder length="0.3" radius="0.025"/>
      </geometry>
    </collision>
  </link>
  <!-- Mano efector final -->
  <joint name="joint_4" type="fixed">
    <origin rpy="0.0 0.0 0.0" xyz="0.0 0.0 0.3"/>
    <parent link="link_3"/>
    <child link="link_4"/>
    <axis xyz="0.0 0.0 1.0"/>
  </joint>
  <!-- Link 4 -->
  <link name="link_4">
    <inertial>
      <origin rpy="0 0 0" xyz="0 0 0.075"/>
      <mass value="1"/>
      <inertia ixx="0.0020833333333333333" ixy="0.0" ixz="0.0" iyy="0.0020833333333333333" iyz="0.0" izz="0.00041666666666666675"/>
    </inertial>
    <visual>
      <origin rpy="0.0 1.570795 0.0" xyz="0.0 0.0 0.025"/>
      <geometry>
        <box size="0.05 0.05 0.15"/>
      </geometry>
      <material name="grey">
        <color rgba="0.5 0.5 0.5 1"/>
      </material>
    </visual>
    <collision>
      <origin rpy="0.0 1.570795 0.0" xyz="0.0 0.0 0.025"/>
      <geometry>
        <box size="0.05 0.05 0.15"/>
      </geometry>
    </collision>
  </link>
</robot>
