<?xml version="1.0"?>
<robot name="robot_name">
    <!-- Mundo (World) -->
    <link name="world"/>
    <joint name="world_joint" type="fixed">
        <origin rpy="0.0 0.0 0.0" xyz="0.0 0.0 0.0"/>
        <parent link="world"/>
        <child link="base_link"/>
    </joint>
    <!-- Base Link -->
    <link name="base_link">
        <inertial>
            <origin xyz="0 0 0.075" rpy="0 0 0"/>
            <mass value="20"/>
            <inertia ixx="0.10416666666666667" ixy="0.0" ixz="0.0" iyy="0.10416666666666667" iyz="0.0" izz="0.13333333333333336"/>
        </inertial>
        <visual>
            <origin xyz="0 0 0.075" rpy="0 0 0"/>
            <geometry>
                <cylinder radius="0.15" length="0.15"/>
            </geometry>
            <material name="grey">
                <color rgba="0.5 0.5 0.5 1"/>
            </material>
        </visual>
        <collision>
            <origin xyz="0 0 0.075" rpy="0 0 0"/>
            <geometry>
                <cylinder radius="0.15" length="0.15"/>
            </geometry>
        </collision>
    </link>
    <joint name="joint_1" type="revolute">
        <origin rpy="0.0 0.0 0.0" xyz="0.0 0.0 0.15"/>
        <parent link="base_link"/>
        <child link="link_1"/>
        <axis xyz="0.0 0.0 1"/>
        <limit effort="300.0" lower="0.0" upper="6.28318" velocity="1.0"/>
    </joint>
    <!-- Brazo -->
    <link name="link_1">
        <inertial>
            <origin xyz="0 0 0.2" rpy="0 0 0"/>
            <mass value="5"/>
            <inertia ixx="0.07083333333333336" ixy="0.0" ixz="0.0" iyy="0.07083333333333336" iyz="0.0" izz="0.008333333333333335"/>
        </inertial>
        <visual>
            <origin xyz="0.0 0.0 0.2" rpy="0.0 0.0 0.0"/>
            <geometry>
                <cylinder length="0.4" radius="0.05"/>
            </geometry>
            <material name="grey">
                <color rgba="0.5 0.5 0.5 1"/>
            </material>
        </visual>
        <collision>
            <origin xyz="0.0 0.0 0.2" rpy="0.0 0.0 0.0"/>
            <geometry>
                <cylinder length="0.4" radius="0.05"/>
            </geometry>
        </collision>
    </link>

    <!-- Codo -->
    <link name="link_1_endlink">
        <inertial>
            <origin xyz="0 0 0.085" rpy="0 0 0"/>
            <mass value="1.6666666666666667"/>
            <inertia ixx="0.005402777777777779" ixy="0.0" ixz="0.0" iyy="0.005402777777777779" iyz="0.0" izz="0.0027777777777777783"/>
        </inertial>
        <visual>
            <origin xyz="0.0 0.0 0.085" rpy="0.0 0.0 0.0"/>
            <geometry>
                <cylinder length="0.17" radius="0.05500000000000001"/>
            </geometry>
            <material name="grey">
                <color rgba="0.5 0.5 0.5 1"/>
            </material>
        </visual>
        <collision>
            <origin xyz="0.0 0.0 0.085" rpy="0.0 0.0 0.0"/>
            <geometry>
                <cylinder length="0.17" radius="0.05500000000000001"/>
            </geometry>
        </collision>
    </link>

    <!-- Articulacion codo -->
    <joint name="link_1_endjoint" type="fixed">
        <origin xyz="-0.05 0.0 0.39" rpy="0.0 1.570795 0.0"/>
        <parent link="link_1"/>
        <child link="link_1_endlink"/>
    </joint>

    <joint name="joint_2" type="revolute">
        <origin xyz="0.085 0.0 0.4" rpy="0.0 0.0 0.0"/>
        <parent link="link_1"/>
        <child link="link_2"/>
        <axis xyz="1.0 0.0 0.0"/>
        <limit effort="1.57" lower="-1.90" upper="1.90" velocity="1.0"/>
    </joint>

    <!-- Antebrazo -->
    <link name="link_2">
        <inertial>
            <origin xyz="0 0 0.25" rpy="0 0 0"/>
            <mass value="3"/>
            <inertia ixx="0.063725" ixy="0.0" ixz="0.0" iyy="0.063725" iyz="0.0" izz="0.0024500000000000004"/>
        </inertial>
        <visual>
            <origin xyz="0.0 0.0 0.25" rpy="0.0 0.0 0.0"/>
            <geometry>
                <cylinder length="0.5" radius="0.035"/>
            </geometry>
            <material name="grey">
                <color rgba="0.5 0.5 0.5 1"/>
            </material>
        </visual>
        <collision>
            <origin xyz="0.0 0.0 0.25" rpy="0.0 0.0 0.0"/>
            <geometry>
                <cylinder length="0.5" radius="0.035"/>
            </geometry>
        </collision>
    </link>

    <!-- Muneca -->
    <link name="link_2_endlink">
        <inertial>
            <origin xyz="0 0 0.060000000000000005" rpy="0 0 0"/>
            <mass value="1.0"/>
            <inertia ixx="0.0016083333333333336" ixy="0.0" ixz="0.0" iyy="0.0016083333333333336" iyz="0.0" izz="0.0008166666666666667"/>
        </inertial>
        <visual>
            <origin xyz="0.0 0.0 0.060000000000000005" rpy="0.0 0.0 0.0"/>
            <geometry>
                <cylinder length="0.12000000000000001" radius="0.038500000000000006"/>
            </geometry>
            <material name="grey">
                <color rgba="0.5 0.5 0.5 1"/>
            </material>
        </visual>
        <collision>
            <origin xyz="0.0 0.0 0.060000000000000005" rpy="0.0 0.0 0.0"/>
            <geometry>
                <cylinder length="0.12000000000000001" radius="0.038500000000000006"/>
            </geometry>
        </collision>
    </link>

    <!-- Articulacion muneca -->
    <joint name="link_2_endjoint" type="fixed">
        <origin xyz="-0.035 0.0 0.49" rpy="0.0 1.570795 0.0"/>
        <parent link="link_2"/>
        <child link="link_2_endlink"/>
    </joint>

    <joint name="joint_3" type="revolute">
        <origin xyz="0.060000000000000005 0.0 0.46499999999999997" rpy="0.0 0.0 0.0"/>
        <parent link="link_2"/>
        <child link="link_3"/>
        <axis xyz="1.0 0.0 0.0"/>
        <limit effort="300.0" lower="0.0" upper="6.28318" velocity="1.0"/>
    </joint>

    <!-- Mano -->
    <link name="link_3">
        <inertial>
            <origin xyz="0 0 0.15" rpy="0 0 0"/>
            <mass value="3"/>
            <inertia ixx="0.023125" ixy="0.0" ixz="0.0" iyy="0.023125" iyz="0.0" izz="0.0012500000000000002"/>
        </inertial>
        <visual>
            <origin xyz="0.0 0.0 0.15" rpy="0.0 0.0 0.0"/>
            <geometry>
                <cylinder length="0.3" radius="0.025"/>
            </geometry>
            <material name="grey">
                <color rgba="0.5 0.5 0.5 1"/>
            </material>
        </visual>
        <collision>
            <origin xyz="0.0 0.0 0.15" rpy="0.0 0.0 0.0"/>
            <geometry>
                <cylinder length="0.3" radius="0.025"/>
            </geometry>
        </collision>
    </link>

    <!-- Mano efector final -->
    <joint name="joint_4" type="fixed">
        <origin xyz="0.0 0.0 0.3" rpy="0.0 0.0 0.0"/>
        <parent link="link_3"/>
        <child link="link_4"/>
        <axis xyz="0.0 0.0 1.0"/>
    </joint>

    <link name="link_4">
        <inertial>
            <origin xyz="0 0 0.075" rpy="0 0 0"/>
            <mass value="1"/>
            <inertia ixx="0.0020833333333333333" ixy="0.0" ixz="0.0" iyy="0.0020833333333333333" iyz="0.0" izz="0.00041666666666666675"/>
        </inertial>
        <visual>
            <origin xyz="0.0 0.0 0.0125" rpy="0.0 1.570795 0.0"/>
            <geometry>
                <box size="0.05 0.05 0.15"/>
            </geometry>
            <material name="grey">
                <color rgba="0.5 0.5 0.5 1"/>
            </material>
        </visual>
        <collision>
            <origin xyz="0.0 0.0 0.0125" rpy="0.0 0.0 0.0"/>
            <geometry>
                <box size="0.05 0.05 0.15"/>
            </geometry>
        </collision>
    </link>

</robot>
